Workbook
Name CL: 'RELEVANCIA-PUNTAJE'!$B$2
Name L: 'RELEVANCIA-PUNTAJE'!$C$2
Name ML: 'RELEVANCIA-PUNTAJE'!$D$2
Name MR: 'RELEVANCIA-PUNTAJE'!$A$3
Name MR_CL: 'RELEVANCIA-PUNTAJE'!$B$3
Name MR_L: 'RELEVANCIA-PUNTAJE'!$C$3
Name MR_ML: 'RELEVANCIA-PUNTAJE'!$D$3
Name MR_NL: 'RELEVANCIA-PUNTAJE'!$E$3
Name MR_PL: 'RELEVANCIA-PUNTAJE'!#REF!
Name MR_TL: 'RELEVANCIA-PUNTAJE'!$B$3
Name NL: 'RELEVANCIA-PUNTAJE'!$E$2
Name PL: 'RELEVANCIA-PUNTAJE'!#REF!
Name PR: 'RELEVANCIA-PUNTAJE'!$A$5
Name PR_ML: 'RELEVANCIA-PUNTAJE'!$D$5
Name PR_NL: 'RELEVANCIA-PUNTAJE'!$E$5
Name PR_PL: 'RELEVANCIA-PUNTAJE'!#REF!
Name PR_TL: 'RELEVANCIA-PUNTAJE'!$B$5
Name RE: 'RELEVANCIA-PUNTAJE'!$A$4
Name RE_ML: 'RELEVANCIA-PUNTAJE'!$D$4
Name RE_NL: 'RELEVANCIA-PUNTAJE'!$E$4
Name RE_PL: 'RELEVANCIA-PUNTAJE'!#REF!
Name RE_TL: 'RELEVANCIA-PUNTAJE'!$B$4
Name TL: 'RELEVANCIA-PUNTAJE'!$B$2

Sheet EVALUACION FASE 3
C2: 0.7 | D2: 0.3 | E2: 1
B3: INTEGRANTES | C3: Nota docente asignatura | D3: Nota comision | E3: Nota final
A4: 1 | B4: GUERRA FLORES CARLOS | C4: =C21 -> 6.5 | D4: =C60 -> 6.5 | E4: =C4*C$2+D4*D$2 -> 6.5
A5: 2 | B5: MARIN FARIAS DIEGO | C5: =C34 -> 6.5 | D5: =C73 -> 6.5 | E5: =C5*C$2+D5*D$2 -> 6.5
A6: 3 | B6: MORALES PERALTA HECTOR ALEXANDER | C6: =C47 -> 6.5 | D6: =C86 -> 6.5 | E6: =C6*C$2+D6*D$2 -> 6.5
A11: DOCENTE | B11: =B4 -> GUERRA FLORES CARLOS | C11: Nivel de Logro | D11: NIVELES DE LOGRO Y PUNTAJES
B12: Aspectos a Evaluar | D12: Completamente logrado | F12: Logrado | H12: Logro Incipiente | J12: No logrado
B13: =RUBRICA!A4 -> 1. Presenta el proyecto considerando la relevancia, objetivos, metodología y desarrollo, de acuerdo a los estándares de calidad de la disciplina. | C13: Completamente logrado | D13: =IF($C13=CL,"X","") -> X | E13: =IF(D13="X",100*0.15,"") -> 15 | F13: =IF($C13=L,"X","") | G13: =IF(F13="X",60*0.15,"") | H13: =IF($C13=ML,"X","") | I13: =IF(H13="X",30*0.15,"") | J13: =IF($C13=NL,"X","") | K13: =IF($J13="X",0,"")
B14: =RUBRICA!A5 -> 2. Presenta las evidencias del Proyecto APT, dando cuenta del cumplimiento de los objetivos y de acuerdo a los estándares de la disciplina. | C14: Completamente logrado | D14: =IF($C14=CL,"X","") -> X | E14: =IF(D14="X",100*0.25,"") -> 25 | F14: =IF($C14=L,"X","") | G14: =IF(F14="X",60*0.25,"") | H14: =IF($C14=ML,"X","") | I14: =IF(H14="X",30*0.25,"") | J14: =IF($C14=NL,"X","") | K14: =IF($J14="X",0,"")
B15: =RUBRICA!A6 -> 3. Responde las preguntas realizadas por la comisión, cumpliendo con los estándares de calidad de la disciplina. | C15: Completamente logrado | D15: =IF($C15=CL,"X","") -> X | E15: =IF(D15="X",100*0.2,"") -> 20 | F15: =IF($C15=L,"X","") | G15: =IF(F15="X",60*0.2,"") | H15: =IF($C15=ML,"X","") | I15: =IF(H15="X",30*0.2,"") | J15: =IF($C15=NL,"X","") | K15: =IF($J15="X",0,"")
B16: =RUBRICA!A7 -> 4. Expone el Proyecto APT, considerando el formato y el tiempo establecido para la presentación. | C16: Logrado | D16: =IF($C16=CL,"X","") | E16: =IF(D16="X",100*0.05,"") | F16: =IF($C16=L,"X","") -> X | G16: =IF(F16="X",60*0.05,"") -> 3 | H16: =IF($C16=ML,"X","") | I16: =IF(H16="X",30*0.05,"") | J16: =IF($C16=NL,"X","") | K16: =IF($J16="X",0,"")
B17: =RUBRICA!A8 -> 5. Expresa sus ideas con fluidez, claridad y precisión, utilizando lenguaje técnico propio de la disciplina. | C17: Logrado | D17: =IF($C17=CL,"X","") | E17: =IF(D17="X",100*0.05,"") | F17: =IF($C17=L,"X","") -> X | G17: =IF(F17="X",60*0.05,"") -> 3 | H17: =IF($C17=ML,"X","") | I17: =IF(H17="X",30*0.05,"") | J17: =IF($C17=NL,"X","") | K17: =IF($J17="X",0,"")
B18: =RUBRICA!A9 -> 6. Entrega la documentación y evidencias requerida por la asignatura de acuerdo a la estructura y nombres solicitados, guardando todas las evidencias de avances en Git | C18: Completamente logrado | D18: =IF($C18=CL,"X","") -> X | E18: =IF(D18="X",100*0.2,"") -> 20 | F18: =IF($C18=L,"X","") | G18: =IF(F18="X",60*0.2,"") | H18: =IF($C18=ML,"X","") | I18: =IF(H18="X",30*0.2,"") | J18: =IF($C18=NL,"X","") | K18: =IF($J18="X",0,"")
B19: =RUBRICA!A10 -> 7. Expone el tema utilizando un lenguaje técnico disciplinar al presentar la propuesta y responde evidenciando un manejo de la información. | C19: Logrado | D19: =IF($C19=CL,"X","") | E19: =IF(D19="X",100*0.1,"") | F19: =IF($C19=L,"X","") -> X | G19: =IF(F19="X",60*0.1,"") -> 6 | H19: =IF($C19=ML,"X","") | I19: =IF(H19="X",30*0.1,"") | J19: =IF($C19=NL,"X","") | K19: =IF($J19="X",0,"")
B20: Puntaje | C20: =E20+G20+I20+K20 -> 92 | E20: =SUM(E13:E19) -> 80 | G20: =SUM(G13:G19) -> 12 | I20: =SUM(I13:I19) -> 0 | K20: =SUM(K13:K19) -> 0
B21: Nota | C21: 6.5
A24: DOCENTE | B24: =B5 -> MARIN FARIAS DIEGO | C24: Nivel de Logro | D24: NIVELES DE LOGRO Y PUNTAJES
B25: Aspectos a Evaluar | D25: Completamente logrado | F25: Logrado | H25: Logro Incipiente | J25: No logrado
B26: =RUBRICA!A4 -> 1. Presenta el proyecto considerando la relevancia, objetivos, metodología y desarrollo, de acuerdo a los estándares de calidad de la disciplina. | C26: Completamente logrado | D26: =IF($C26=CL,"X","") -> X | E26: =IF(D26="X",100*0.15,"") -> 15 | F26: =IF($C26=L,"X","") | G26: =IF(F26="X",60*0.15,"") | H26: =IF($C26=ML,"X","") | I26: =IF(H26="X",30*0.15,"") | J26: =IF($C26=NL,"X","") | K26: =IF($J26="X",0,"")
B27: =RUBRICA!A5 -> 2. Presenta las evidencias del Proyecto APT, dando cuenta del cumplimiento de los objetivos y de acuerdo a los estándares de la disciplina. | C27: Completamente logrado | D27: =IF($C27=CL,"X","") -> X | E27: =IF(D27="X",100*0.25,"") -> 25 | F27: =IF($C27=L,"X","") | G27: =IF(F27="X",60*0.25,"") | H27: =IF($C27=ML,"X","") | I27: =IF(H27="X",30*0.25,"") | J27: =IF($C27=NL,"X","") | K27: =IF($J27="X",0,"")
B28: =RUBRICA!A6 -> 3. Responde las preguntas realizadas por la comisión, cumpliendo con los estándares de calidad de la disciplina. | C28: Completamente logrado | D28: =IF($C28=CL,"X","") -> X | E28: =IF(D28="X",100*0.2,"") -> 20 | F28: =IF($C28=L,"X","") | G28: =IF(F28="X",60*0.2,"") | H28: =IF($C28=ML,"X","") | I28: =IF(H28="X",30*0.2,"") | J28: =IF($C28=NL,"X","") | K28: =IF($J28="X",0,"")
B29: =RUBRICA!A7 -> 4. Expone el Proyecto APT, considerando el formato y el tiempo establecido para la presentación. | C29: Logrado | D29: =IF($C29=CL,"X","") | E29: =IF(D29="X",100*0.05,"") | F29: =IF($C29=L,"X","") -> X | G29: =IF(F29="X",60*0.05,"") -> 3 | H29: =IF($C29=ML,"X","") | I29: =IF(H29="X",30*0.05,"") | J29: =IF($C29=NL,"X","") | K29: =IF($J29="X",0,"")
B30: =RUBRICA!A8 -> 5. Expresa sus ideas con fluidez, claridad y precisión, utilizando lenguaje técnico propio de la disciplina. | C30: Logrado | D30: =IF($C30=CL,"X","") | E30: =IF(D30="X",100*0.05,"") | F30: =IF($C30=L,"X","") -> X | G30: =IF(F30="X",60*0.05,"") -> 3 | H30: =IF($C30=ML,"X","") | I30: =IF(H30="X",30*0.05,"") | J30: =IF($C30=NL,"X","") | K30: =IF($J30="X",0,"")
B31: =RUBRICA!A9 -> 6. Entrega la documentación y evidencias requerida por la asignatura de acuerdo a la estructura y nombres solicitados, guardando todas las evidencias de avances en Git | C31: Completamente logrado | D31: =IF($C31=CL,"X","") -> X | E31: =IF(D31="X",100*0.2,"") -> 20 | F31: =IF($C31=L,"X","") | G31: =IF(F31="X",60*0.2,"") | H31: =IF($C31=ML,"X","") | I31: =IF(H31="X",30*0.2,"") | J31: =IF($C31=NL,"X","") | K31: =IF($J31="X",0,"")
B32: =RUBRICA!A10 -> 7. Expone el tema utilizando un lenguaje técnico disciplinar al presentar la propuesta y responde evidenciando un manejo de la información. | C32: Logrado | D32: =IF($C32=CL,"X","") | E32: =IF(D32="X",100*0.1,"") | F32: =IF($C32=L,"X","") -> X | G32: =IF(F32="X",60*0.1,"") -> 6 | H32: =IF($C32=ML,"X","") | I32: =IF(H32="X",30*0.1,"") | J32: =IF($C32=NL,"X","") | K32: =IF($J32="X",0,"")
B33: Puntaje | C33: =E33+G33+I33+K33 -> 92 | E33: =SUM(E26:E32) -> 80 | G33: =SUM(G26:G32) -> 12 | I33: =SUM(I26:I32) -> 0 | K33: =SUM(K26:K32) -> 0
B34: Nota | C34: 6.5
A37: DOCENTE | B37: =B6 -> MORALES PERALTA HECTOR ALEXANDER | C37: Nivel de Logro | D37: NIVELES DE LOGRO Y PUNTAJES
B38: Aspectos a Evaluar | D38: Completamente logrado | F38: Logrado | H38: Logro Incipiente | J38: No logrado
B39: =RUBRICA!A4 -> 1. Presenta el proyecto considerando la relevancia, objetivos, metodología y desarrollo, de acuerdo a los estándares de calidad de la disciplina. | C39: Completamente logrado | D39: =IF($C39=CL,"X","") -> X | E39: =IF(D39="X",100*0.15,"") -> 15 | F39: =IF($C39=L,"X","") | G39: =IF(F39="X",60*0.15,"") | H39: =IF($C39=ML,"X","") | I39: =IF(H39="X",30*0.15,"") | J39: =IF($C39=NL,"X","") | K39: =IF($J39="X",0,"")
B40: =RUBRICA!A5 -> 2. Presenta las evidencias del Proyecto APT, dando cuenta del cumplimiento de los objetivos y de acuerdo a los estándares de la disciplina. | C40: Completamente logrado | D40: =IF($C40=CL,"X","") -> X | E40: =IF(D40="X",100*0.25,"") -> 25 | F40: =IF($C40=L,"X","") | G40: =IF(F40="X",60*0.25,"") | H40: =IF($C40=ML,"X","") | I40: =IF(H40="X",30*0.25,"") | J40: =IF($C40=NL,"X","") | K40: =IF($J40="X",0,"")
B41: =RUBRICA!A6 -> 3. Responde las preguntas realizadas por la comisión, cumpliendo con los estándares de calidad de la disciplina. | C41: Completamente logrado | D41: =IF($C41=CL,"X","") -> X | E41: =IF(D41="X",100*0.2,"") -> 20 | F41: =IF($C41=L,"X","") | G41: =IF(F41="X",60*0.2,"") | H41: =IF($C41=ML,"X","") | I41: =IF(H41="X",30*0.2,"") | J41: =IF($C41=NL,"X","") | K41: =IF($J41="X",0,"")
B42: =RUBRICA!A7 -> 4. Expone el Proyecto APT, considerando el formato y el tiempo establecido para la presentación. | C42: Logrado | D42: =IF($C42=CL,"X","") | E42: =IF(D42="X",100*0.05,"") | F42: =IF($C42=L,"X","") -> X | G42: =IF(F42="X",60*0.05,"") -> 3 | H42: =IF($C42=ML,"X","") | I42: =IF(H42="X",30*0.05,"") | J42: =IF($C42=NL,"X","") | K42: =IF($J42="X",0,"")
B43: =RUBRICA!A8 -> 5. Expresa sus ideas con fluidez, claridad y precisión, utilizando lenguaje técnico propio de la disciplina. | C43: Logrado | D43: =IF($C43=CL,"X","") | E43: =IF(D43="X",100*0.05,"") | F43: =IF($C43=L,"X","") -> X | G43: =IF(F43="X",60*0.05,"") -> 3 | H43: =IF($C43=ML,"X","") | I43: =IF(H43="X",30*0.05,"") | J43: =IF($C43=NL,"X","") | K43: =IF($J43="X",0,"")
B44: =RUBRICA!A9 -> 6. Entrega la documentación y evidencias requerida por la asignatura de acuerdo a la estructura y nombres solicitados, guardando todas las evidencias de avances en Git | C44: Completamente logrado | D44: =IF($C44=CL,"X","") -> X | E44: =IF(D44="X",100*0.2,"") -> 20 | F44: =IF($C44=L,"X","") | G44: =IF(F44="X",60*0.2,"") | H44: =IF($C44=ML,"X","") | I44: =IF(H44="X",30*0.2,"") | J44: =IF($C44=NL,"X","") | K44: =IF($J44="X",0,"")
B45: =RUBRICA!A10 -> 7. Expone el tema utilizando un lenguaje técnico disciplinar al presentar la propuesta y responde evidenciando un manejo de la información. | C45: Logrado | D45: =IF($C45=CL,"X","") | E45: =IF(D45="X",100*0.1,"") | F45: =IF($C45=L,"X","") -> X | G45: =IF(F45="X",60*0.1,"") -> 6 | H45: =IF($C45=ML,"X","") | I45: =IF(H45="X",30*0.1,"") | J45: =IF($C45=NL,"X","") | K45: =IF($J45="X",0,"")
B46: Puntaje | C46: =E46+G46+I46+K46 -> 92 | E46: =SUM(E39:E45) -> 80 | G46: =SUM(G39:G45) -> 12 | I46: =SUM(I39:I45) -> 0 | K46: =SUM(K39:K45) -> 0
B47: Nota | C47: 6.5
A50: COMISION 1 | B50: =B4 -> GUERRA FLORES CARLOS | C50: Nivel de Logro | D50: NIVELES DE LOGRO Y PUNTAJES
B51: Aspectos a Evaluar | D51: Completamente logrado | F51: Logrado | H51: Logro Incipiente | J51: No logrado
...

Sheet RUBRICA
A1: Indicador de Evaluación | B1: Categorías de Respuesta | F1: Ponderación del Indicador de Evaluación
B2: Completamente Logrado (100%) | C2: Logrado (60%) | D2: Logro incipiente | E2: No logrado
D3: 0.3 | E3: 0
A4: 1. Presenta el proyecto considerando la relevancia, objetivos, metodología y desarrollo, de acuerdo a los estándares de calidad de la disciplina. | B4: Presenta el proyecto mencionando la relevancia, objetivos, metodología y desarrollo de este y todos los aspectos presentados cumplen con los estándares de calidad de la disciplina. | C4: Presenta el proyecto mencionando solo 2 o 3 aspectos de este (relevancia, objetivos, metodología y desarrollo) y todos los aspectos mencionados cumplen con los estándares de calidad de la disciplina. | D4: Presenta el proyecto mencionado algunos o todos los aspectos de este (relevancia, objetivos, metodología y desarrollo) y la mayoría de ellos no cumple con los estándares de calidad de la disciplina. | E4: Presenta el proyecto y los aspectos considerados no cumplen con los estándares de la disciplina. | F4: 15
A5: 2. Presenta las evidencias del Proyecto APT, dando cuenta del cumplimiento de los objetivos y de acuerdo a los estándares de la disciplina. | B5: Presenta evidencias que cumplen los estándares de la disciplina y dan cuenta del cumplimiento de los objetivos del Proyecto APT. | C5: Presenta evidencias que requieren ajustes menores de acuerdo a los estándares de la disciplina y dan cuenta del cumplimiento de los objetivos del Proyecto APT. | D5: Presenta evidencias que requieren ajustes mayores de acuerdo a los estándares de la disciplina y dan cuenta parcialmente del cumplimiento de los objetivos del Proyecto APT. | E5: Presenta evidencias finales que no cumplen los estándares de la disciplina o no presenta evidencias del Proyecto APT. | F5: 25
A6: 3. Responde las preguntas realizadas por la comisión, cumpliendo con los estándares de calidad de la disciplina. | B6: Responde todas las preguntas realizadas por la comisión cumpliendo con los estándares de calidad de la disciplina. | C6: Responde todas las preguntas realizadas por la comisión cumpliendo con los estándares de calidad de la disciplina, pero presentando leves imprecisiones. | D6: Responde todas o algunas de las preguntas realizadas por la comisión, pero presenta importantes fallas de acuerdo a los estándares de calidad de la disciplina. | E6: No responde las preguntas de la comisión o las respuestas no cumplen con los estándares de calidad de la disciplina. | F6: 20
A7: 4. Expone el Proyecto APT, considerando el formato y el tiempo establecido para la presentación. | B7: Expone el Proyecto APT, respetando el formato y tiempo establecidos por la disciplina. | C7: Expone el Proyecto APT, respetando el tiempo establecido para la presentación, pero algún aspecto del formato no cumple con lo establecido por la disciplina. | D7: Expone el Proyecto APT, pero excede el tiempo establecido para la presentación y la mayoría de los aspectos del formato no cumplen con lo establecido por la disciplina. | E7: La presentación no cumple el tiempo ni el formato establecido por la disciplina. | F7: 5
A8: 5. Expresa sus ideas con fluidez, claridad y precisión, utilizando lenguaje técnico propio de la disciplina. | B8: Expresa sus ideas con fluidez, claridad y precisión y siempre utiliza adecuadamente el lenguaje técnico de la disciplina. | C8: Expresa sus ideas cumpliendo con uno o dos de los tres elementos: fluidez, claridad y/o precisión y presenta errores menores en el lenguaje técnico de la disciplina. | D8: Expresa sus ideas cumpliendo con al menos uno de los tres elementos: fluidez, claridad y/o precisión y presenta errores importantes en el lenguaje técnico de la disciplina y presenta errores importantes en el lenguaje técnico de la disciplina. | E8: No expresa sus ideas con fluidez, ni claridad ni precisión ni con un lenguaje técnico de la disciplina que sea adecuado. | F8: 5
A9: 6. Entrega la documentación y evidencias requerida por la asignatura de acuerdo a la estructura y nombres solicitados, guardando todas las evidencias de avances en Git | B9: Entrega la documentación y evidencias requeridas por la asignatura de acuerdo a la estructura y nombres solicitados, guardando todas las evidencias de avances en Git | C9: Entrega la documentación y evidencias requeridas por la asignatura de acuerdo a la estructura y nombres solicitados, guardando algunas de las evidencias de avances en Git | D9: Entrega la documentación y evidencias requeridas por la asignatura sin una la estructura y nombres solicitados, guardando algunas de las evidencias de avances en Git | E9: No entrega a través de Git la documentación y evidencias de avance requeridas por la asignatura | F9: 20
A10: 7. Expone el tema utilizando un lenguaje técnico disciplinar al presentar la propuesta y responde evidenciando un manejo de la información. | B10: Expone el tema utilizando un lenguaje técnico disciplinar al presentar la propuesta y responde evidenciando un manejo de la información en todo momento | C10: Expone el tema utilizando un lenguaje técnico disciplinar al presentar la propuesta y responde evidenciando un manejo de la información la mayoría del tiempo. | D10: Expone el tema utilizando un lenguaje técnico disciplinar al presentar la propuesta y responde evidenciando un manejo de la información la mitad del tiempo. | E10: Expone el tema utilizando un lenguaje técnico disciplinar al presentar la propuesta y responde evidenciando un manejo de la información en menos de la mitad del tiempo. | F10: 10

Sheet ESCALA_IEP
A1: Puntaje | B1: Nota
A2: 0 | B2: 1
A3: 0.5 | B3: 1
A4: 1 | B4: 1.1
A5: 1.5 | B5: 1.1
A6: 2 | B6: 1.1
A7: 2.5 | B7: 1.1
A8: 3 | B8: 1.2
A9: 3.5 | B9: 1.2
A10: 4 | B10: 1.2
A11: 4.5 | B11: 1.2
A12: 5 | B12: 1.3
A13: 5.5 | B13: 1.3
... A202: 100 | B202: 7

Sheet ESCALA_PRESENTACION
A1: PUNTOS | B1: NOTA
A2: 0 | B2: 1
A3: 1 | B3: 1.1
A4: 2 | B4: 1.2
A5: 3 | B5: 1.3
A6: 4 | B6: 1.4
A7: 5 | B7: 1.5
A8: 6 | B8: 1.6
A9: 7 | B9: 1.7
A10: 8 | B10: 1.8
A11: 9 | B11: 1.9
A12: 10 | B12: 2
A13: 11 | B13: 2.1
... A54: 52 | B54: 7

Sheet ESCALA_TRAB_EQUIP
A1: Puntaje | B1: Nota
A2: 0 | B2: 1
A3: 0.5 | B3: 1.1
A4: 1 | B4: 1.3
A5: 1.5 | B5: 1.4
A6: 2 | B6: 1.5
A7: 2.5 | B7: 1.6
A8: 3 | B8: 1.8
A9: 3.5 | B9: 1.9
A10: 4 | B10: 2
A11: 4.5 | B11: 2.1
A12: 5 | B12: 2.3
A13: 5.5 | B13: 2.4
... A42: 20 | B42: 7

Sheet RELEVANCIA-PUNTAJE
A1: Relevancia | B1: Puntaje
B2: Completamente logrado | C2: Logrado | D2: Logro incipiente | E2: No logrado
A3: Muy Relevante | B3: 4 | C3: 3 | D3: 2 | E3: 0
